Workbook

Sheet Analysis
A1: REVENUE | B1: Q1 | C1: Q2 | D1: Q3 | E1: Q4 | F1: FY 2024 | G1: FY 2023 | H1: YoY $M | I1: YoY % | J1: SEGMENT CONTRIBUTION%
A2: Software | B2: ='--Quarterly_PL'!C5 -> 5902 | C2: ='--Quarterly_PL'!D5 -> 6740 | D2: ='--Quarterly_PL'!E5 -> 6520 | E2: ='--Quarterly_PL'!F5 -> 7116 | F2: ='--Quarterly_PL'!G5 -> 26278 | G2: ='--Quarterly_PL'!H5 -> 24459 | H2: ='--Quarterly_PL'!I5 -> 1819 | I2: ='--Quarterly_PL'!J5 -> 0.074369353 | J2: =F2/$F$6 -> 0.41875289
A3: Consulting | B3: ='--Quarterly_PL'!C6 -> 5214 | C3: ='--Quarterly_PL'!D6 -> 5200 | D3: ='--Quarterly_PL'!E6 -> 5150 | E3: ='--Quarterly_PL'!F6 -> 5336 | F3: ='--Quarterly_PL'!G6 -> 20900 | G3: ='--Quarterly_PL'!H6 -> 21072 | H3: ='--Quarterly_PL'!I6 -> -172 | I3: ='--Quarterly_PL'!J6 -> -0.0081624905 | J3: =Analysis!$F3/$F$6 -> 0.33305181
A4: Infrastructure | B4: ='--Quarterly_PL'!C7 -> 2955 | C4: ='--Quarterly_PL'!D7 -> 3649 | D4: ='--Quarterly_PL'!E7 -> 3043 | E4: ='--Quarterly_PL'!F7 -> 4148 | F4: ='--Quarterly_PL'!G7 -> 13795 | G4: ='--Quarterly_PL'!H7 -> 14228 | H4: ='--Quarterly_PL'!I7 -> -433 | I4: ='--Quarterly_PL'!J7 -> -0.030432949 | J4: =Analysis!$F4/$F$6 -> 0.21983013
A5: Financing & Other | B5: ='--Quarterly_PL'!C8 -> 389 | C5: ='--Quarterly_PL'!D8 -> 211 | D5: ='--Quarterly_PL'!E8 -> 257 | E5: ='--Quarterly_PL'!F8 -> 923 | F5: ='--Quarterly_PL'!G8 -> 1780 | G5: ='--Quarterly_PL'!H8 -> 2101 | H5: ='--Quarterly_PL'!I8 -> -321 | I5: ='--Quarterly_PL'!J8 -> -0.15278439 | J5: =Analysis!$F5/$F$6 -> 0.028365178
A6: TOTAL REVENUE | B6: =SUM(B2:B5) -> 14460 | C6: =SUM(C2:C5) -> 15800 | D6: =SUM(D2:D5) -> 14970 | E6: =SUM(E2:E5) -> 17523 | F6: =SUM(F2:F5) -> 62753 | G6: =SUM(G2:G5) -> 61860 | H6: =SUM(H2:H5) -> 893 | I6: ='--Quarterly_PL'!J9 -> 0.014435823 | J6: =SUM(J2:J5) -> 1
A9: COST OF REVENUE | B9: Q1 | C9: Q2 | D9: Q3 | E9: Q4 | F9: FY 2024 | G9: FY 2023 | H9: YoY $M | I9: YoY %
A10: Cost of Software | B10: ='--Quarterly_PL'!C12 -> 1052 | C10: ='--Quarterly_PL'!D12 -> 1145 | D10: ='--Quarterly_PL'!E12 -> 1108 | E10: ='--Quarterly_PL'!F12 -> 1210 | F10: ='--Quarterly_PL'!G12 -> 4515 | G10: ='--Quarterly_PL'!H12 -> 4622 | H10: ='--Quarterly_PL'!I12 -> -107 | I10: ='--Quarterly_PL'!J12 -> -0.023150151
A11: Cost of Consulting | B11: ='--Quarterly_PL'!C13 -> 3809 | C11: ='--Quarterly_PL'!D13 -> 3796 | D11: ='--Quarterly_PL'!E13 -> 3762 | E11: ='--Quarterly_PL'!F13 -> 3895 | F11: ='--Quarterly_PL'!G13 -> 15262 | G11: ='--Quarterly_PL'!H13 -> 15505 | H11: ='--Quarterly_PL'!I13 -> -243 | I11: ='--Quarterly_PL'!J13 -> -0.015672364
A12: Cost of Infrastructure | B12: ='--Quarterly_PL'!C14 -> 1655 | C12: ='--Quarterly_PL'!D14 -> 1606 | D12: ='--Quarterly_PL'!E14 -> 1694 | E12: ='--Quarterly_PL'!F14 -> 1838 | F12: ='--Quarterly_PL'!G14 -> 6793 | G12: ='--Quarterly_PL'!H14 -> 6969 | H12: ='--Quarterly_PL'!I14 -> -176 | I12: ='--Quarterly_PL'!J14 -> -0.025254699
A13: Cost of Financing & Other | B13: ='--Quarterly_PL'!C15 -> 74 | C13: ='--Quarterly_PL'!D15 -> 70 | D13: ='--Quarterly_PL'!E15 -> 68 | E13: ='--Quarterly_PL'!F15 -> 68 | F13: ='--Quarterly_PL'!G15 -> 280 | G13: ='--Quarterly_PL'!H15 -> 303 | H13: ='--Quarterly_PL'!I15 -> -23 | I13: ='--Quarterly_PL'!J15 -> -0.075907591
A14: TOTAL COGS | B14: ='--Quarterly_PL'!C16 -> 6590 | C14: ='--Quarterly_PL'!D16 -> 6617 | D14: ='--Quarterly_PL'!E16 -> 6632 | E14: ='--Quarterly_PL'!F16 -> 7011 | F14: ='--Quarterly_PL'!G16 -> 26850 | G14: ='--Quarterly_PL'!H16 -> 27399 | H14: ='--Quarterly_PL'!I16 -> -549 | I14: ='--Quarterly_PL'!J16 -> -0.020037228
A17: GROSS PROFIT | B17: Q1 | C17: Q2 | D17: Q3 | E17: Q4 | F17: FY 2024 | G17: FY 2023 | H17: YoY $M | I17: YoY %
A18: Gross profit | B18: =('--Quarterly_PL'!C19)*1 -> 7870 | C18: =('--Quarterly_PL'!D19)*1 -> 9183 | D18: =('--Quarterly_PL'!E19)*1 -> 8338 | E18: =('--Quarterly_PL'!F19)*1 -> 10512 | F18: =('--Quarterly_PL'!G19)*1 -> 35903 | G18: =('--Quarterly_PL'!H19)*1 -> 34461 | H18: =Table7[[#This Row],[FY 2024]]-Table7[[#This Row],[FY 2023]] -> 1442 | I18: ='--Quarterly_PL'!J19 -> 0.041844404
A19: Gross profit margin | B19: =('--Quarterly_PL'!C20)*1 -> 0.544 | C19: =('--Quarterly_PL'!D20)*1 -> 0.581 | D19: =('--Quarterly_PL'!E20)*1 -> 0.557 | E19: =('--Quarterly_PL'!F20)*1 -> 0.6 | F19: =('--Quarterly_PL'!G20)*1 -> 0.572 | G19: =('--Quarterly_PL'!H20)*1 -> 0.557 | H19: =Table7[[#This Row],[FY 2024]]-Table7[[#This Row],[FY 2023]] -> 0.015 | I19: ='--Quarterly_PL'!J20 -> 0
P20: 1
A21: OPERATING EXPENSES | B21: Q1 | C21: Q2 | D21: Q3 | E21: Q4 | F21: FY 2024 | G21: FY 2023 | H21: YoY $M | I21: YoY %
A22: R&D Expense | B22: ='--Quarterly_PL'!C23 -> 1673 | C22: ='--Quarterly_PL'!D23 -> 1682 | D22: ='--Quarterly_PL'!E23 -> 1700 | E22: ='--Quarterly_PL'!F23 -> 1752 | F22: ='--Quarterly_PL'!G23 -> 6807 | G22: ='--Quarterly_PL'!H23 -> 6639 | H22: ='--Quarterly_PL'!I23 -> 168 | I22: ='--Quarterly_PL'!J23 -> 0.025305016
A23: SG&A Expense | B23: ='--Quarterly_PL'!C24 -> 4098 | C23: ='--Quarterly_PL'!D24 -> 3979 | D23: ='--Quarterly_PL'!E24 -> 3830 | E23: ='--Quarterly_PL'!F24 -> 4261 | F23: ='--Quarterly_PL'!G24 -> 16168 | G23: ='--Quarterly_PL'!H24 -> 15603 | H23: ='--Quarterly_PL'!I24 -> 565 | I23: ='--Quarterly_PL'!J24 -> 0.036210985
A24: Pension Settlement Charge | B24: ='--Quarterly_PL'!C25 -> 0 | C24: ='--Quarterly_PL'!D25 -> 0 | D24: ='--Quarterly_PL'!E25 -> 3100 | E24: ='--Quarterly_PL'!F25 -> 0 | F24: ='--Quarterly_PL'!G25 -> 3100 | G24: ='--Quarterly_PL'!H25 -> 0 | H24: ='--Quarterly_PL'!I25 -> 3100 | I24: ='--Quarterly_PL'!J25 -> NM
A25: Other (Income)/Expense | B25: ='--Quarterly_PL'!C26 -> 195 | C25: ='--Quarterly_PL'!D26 -> 183 | D25: ='--Quarterly_PL'!E26 -> 210 | E25: ='--Quarterly_PL'!F26 -> 0 | F25: ='--Quarterly_PL'!G26 -> 2779 | G25: ='--Quarterly_PL'!H26 -> 3368 | H25: ='--Quarterly_PL'!I26 -> -589 | I25: ='--Quarterly_PL'!J26 -> -0.17488124
A26: TOTAL OPERATING EXPENSES | B26: ='--Quarterly_PL'!C27 -> 5966 | C26: ='--Quarterly_PL'!D27 -> 5844 | D26: ='--Quarterly_PL'!E27 -> 8840 | E26: ='--Quarterly_PL'!F27 -> 6004 | F26: ='--Quarterly_PL'!G27 -> 25854 | G26: ='--Quarterly_PL'!H27 -> 25610 | H26: ='--Quarterly_PL'!I27 -> 244 | I26: ='--Quarterly_PL'!J27 -> 0.0095275283
A29: EBIT | B29: Q1 | C29: Q2 | D29: Q3 | E29: Q4 | F29: FY 2024 | G29: FY 2023 | H29: YoY $M | I29: YoY %
A30: EBIT (Operating Income) | B30: =('--Quarterly_PL'!C30)*1 -> 1904 | C30: =('--Quarterly_PL'!D30)*1 -> 3339 | D30: =('--Quarterly_PL'!E30)*1 -> -502 | E30: =('--Quarterly_PL'!F30)*1 -> 4508 | F30: =('--Quarterly_PL'!G30)*1 -> 10049 | G30: =('--Quarterly_PL'!H30)*1 -> 8851 | H30: =Table9[[#This Row],[FY 2024]]-Table9[[#This Row],[FY 2023]] -> 1198 | I30: ='--Quarterly_PL'!J30 -> 0.13535194
A31: EBIT Margin % | B31: =('--Quarterly_PL'!C31)*1 -> 0.132 | C31: =('--Quarterly_PL'!D31)*1 -> 0.211 | D31: =('--Quarterly_PL'!E31)*1 -> -0.034 | E31: =('--Quarterly_PL'!F31)*1 -> 0.257 | F31: =('--Quarterly_PL'!G31)*1 -> 0.16 | G31: =('--Quarterly_PL'!H31)*1 -> 0.143 | H31: =Table9[[#This Row],[FY 2024]]-Table9[[#This Row],[FY 2023]] -> 0.017 | I31: ='--Quarterly_PL'!J31 -> 0
A34: NET INCOME | B34: Q1 | C34: Q2 | D34: Q3 | E34: Q4 | F34: FY 2024 | G34: FY 2023 | H34: YoY $M | I34: YoY %
A35: NET INCOME | B35: ='--Quarterly_PL'!C34 -> 878 | C35: ='--Quarterly_PL'!D34 -> 2591 | D35: ='--Quarterly_PL'!E34 -> -308 | E35: ='--Quarterly_PL'!F34 -> 2862 | F35: ='--Quarterly_PL'!G34 -> 6023 | G35: ='--Quarterly_PL'!H34 -> 7502 | H35: =Table10[[#This Row],[FY 2024]]-Table10[[#This Row],[FY 2023]] -> -1479 | I35: ='--Quarterly_PL'!J34 -> -0.19714743
A36: Net Income Margin % | B36: ='--Quarterly_PL'!C35 -> 6.1% | C36: ='--Quarterly_PL'!D35 -> 16.4% | D36: ='--Quarterly_PL'!E35 -> -2.1% | E36: ='--Quarterly_PL'!F35 -> 16.3% | F36: ='--Quarterly_PL'!G35 -> 9.6% | G36: ='--Quarterly_PL'!H35 -> 12.1% | H36: =Table10[[#This Row],[FY 2024]]-Table10[[#This Row],[FY 2023]] -> -0.025 | I36: ='--Quarterly_PL'!J35 -> 0
A39: NON-GAAP EPS | B39: Q1 | C39: Q2 | D39: Q3 | E39: Q4 | F39: FY 2024 | G39: FY 2023 | H39: YoY $M | I39: YoY %
A40: Operating Non-GAAP EPS | B40: ='--Quarterly_PL'!C36 -> $2.31 | C40: ='--Quarterly_PL'!D36 -> $2.43 | D40: ='--Quarterly_PL'!E36 -> $2.30 | E40: ='--Quarterly_PL'!F36 -> $3.29 | F40: ='--Quarterly_PL'!G36 -> $10.33 | G40: ='--Quarterly_PL'!H36 -> $9.62 | H40: =Table11[[#This Row],[FY 2024]]-Table11[[#This Row],[FY 2023]] -> 0.71 | I40: =Table11[[#This Row],[YoY $M]]/Table11[[#This Row],[FY 2023]] -> 0.073804574
A43: CASH FLOW | B43: Q1 | C43: Q2 | D43: Q3 | E43: Q4 | F43: FY 2024 | G43: FY 2023 | H43: YoY $M | I43: YoY %
A44: Free Cash Flow | B44: ='--Quarterly_PL'!C37 -> 1900 | C44: ='--Quarterly_PL'!D37 -> 2600 | D44: ='--Quarterly_PL'!E37 -> 2090 | E44: ='--Quarterly_PL'!F37 -> 5900 | F44: ='--Quarterly_PL'!G37 -> 12490 | G44: ='--Quarterly_PL'!H37 -> 11248 | H44: ='--Quarterly_PL'!I37 -> 1242 | I44: ='--Quarterly_PL'!J37 -> 0.11041963
A46: REVENUE VS EXPENSE
A47: QUARTER | B47: REVENUE | C47: EXPENSES
A48: Q1 | B48: =B6 -> 14460 | C48: =B14 -> 6590
A49: Q2 | B49: =C6 -> 15800 | C49: =C14 -> 6617
A50: Q3 | B50: =D6 -> 14970 | C50: =D14 -> 6632
A51: Q4 | B51: =E6 -> 17523 | C51: =E14 -> 7011
A53: NET INCOME VS OPERATING INCOME | B53: Q1 | C53: Q2 | D53: Q3 | E53: Q4
A54: Net Income | B54: =B35 -> 878 | C54: =C35 -> 2591 | D54: =D35 -> -308 | E54: =E35 -> 2862
...

Sheet DASHBOARD

Sheet --Quarterly_PL
A1: IBM Corporation — Quarterly P&L Summary | FY 2024 vs FY 2023 (USD $M)
A2: Source: IBM 2024 Annual Report (SEC 10-K Exhibit 13, filed Feb 25 2025) & IBM Quarterly Earnings Releases
A3: P&L Line Item | B3: Category | C3: Q1 2024 | D3: Q2 2024 | E3: Q3 2024 | F3: Q4 2024 | G3: FY 2024 | H3: FY 2023 | I3: YoY $M | J3: YoY % | K3: Notes
A4: ── REVENUE ──
A5: Software Revenue | B5: Revenue | C5: 5902 | D5: 6740 | E5: 6520 | F5: 7116 | G5: 26278 | H5: 24459 | I5: =G5-H5 -> 1819 | J5: =IF(H5<>0,(G5-H5)/ABS(H5),"NM") -> 0.074369353 | K5: Red Hat up 14% in Q3; highest AI growth
A6: Consulting Revenue | B6: Revenue | C6: 5214 | D6: 5200 | E6: 5150 | F6: 5336 | G6: 20900 | H6: 21072 | I6: =G6-H6 -> -172 | J6: =IF(H6<>0,(G6-H6)/ABS(H6),"NM") -> -0.0081624905 | K6: Slight decline; macro headwinds
A7: Infrastructure Revenue | B7: Revenue | C7: 2955 | D7: 3649 | E7: 3043 | F7: 4148 | G7: 13795 | H7: 14228 | I7: =G7-H7 -> -433 | J7: =IF(H7<>0,(G7-H7)/ABS(H7),"NM") -> -0.030432949 | K7: z16 mainframe late in product cycle
A8: Financing & Other | B8: Revenue | C8: 389 | D8: 211 | E8: 257 | F8: 923 | G8: 1780 | H8: 2101 | I8: =G8-H8 -> -321 | J8: =IF(H8<>0,(G8-H8)/ABS(H8),"NM") -> -0.15278439 | K8: Includes IBM client financing + eliminations
A9: TOTAL REVENUE | B9: Revenue | C9: 14460 | D9: 15800 | E9: 14970 | F9: 17523 | G9: 62753 | H9: 61860 | I9: =G9-H9 -> 893 | J9: =IF(H9<>0,(G9-H9)/ABS(H9),"NM") -> 0.014435823 | K9: FY24 +1.4% GAAP; +3.0% constant currency
A11: ── COST OF REVENUE ──
A12: Cost of Software | B12: COGS | C12: 1052 | D12: 1145 | E12: 1108 | F12: 1210 | G12: 4515 | H12: 4622 | I12: =G12-H12 -> -107 | J12: =IF(H12<>0,(G12-H12)/ABS(H12),"NM") -> -0.023150151 | K12: Software ~83% gross margin (Q3)
A13: Cost of Consulting | B13: COGS | C13: 3809 | D13: 3796 | E13: 3762 | F13: 3895 | G13: 15262 | H13: 15505 | I13: =G13-H13 -> -243 | J13: =IF(H13<>0,(G13-H13)/ABS(H13),"NM") -> -0.015672364 | K13: Consulting gross margin ~27%
A14: Cost of Infrastructure | B14: COGS | C14: 1655 | D14: 1606 | E14: 1694 | F14: 1838 | G14: 6793 | H14: 6969 | I14: =G14-H14 -> -176 | J14: =IF(H14<>0,(G14-H14)/ABS(H14),"NM") -> -0.025254699 | K14: Infrastructure gross margin ~51%
A15: Cost of Financing & Other | B15: COGS | C15: 74 | D15: 70 | E15: 68 | F15: 68 | G15: 280 | H15: 303 | I15: =G15-H15 -> -23 | J15: =IF(H15<>0,(G15-H15)/ABS(H15),"NM") -> -0.075907591
A16: TOTAL COGS | B16: COGS | C16: 6590 | D16: 6617 | E16: 6632 | F16: 7011 | G16: 26850 | H16: 27399 | I16: =G16-H16 -> -549 | J16: =IF(H16<>0,(G16-H16)/ABS(H16),"NM") -> -0.020037228 | K16: FY24 COGS -2.0% YoY — cost discipline
A18: ── GROSS PROFIT ──
A19: Gross Profit | B19: Gross Profit | C19: 7870 | D19: 9183 | E19: 8338 | F19: 10512 | G19: 35903 | H19: 34461 | I19: =G19-H19 -> 1442 | J19: =IF(H19<>0,(G19-H19)/ABS(H19),"NM") -> 0.041844404 | K19: GP growing faster than revenue
A20: Gross Profit Margin % | B20: Gross Profit | C20: 54.4% | D20: 58.1% | E20: 55.7% | F20: 0.6 | G20: 0.572 | H20: 0.557 | I20: FY24 +1.5 pts — favorable mix shift to Software | K20: FY24 +1.5 pts — favorable mix shift to Software
A22: ── OPERATING EXPENSES ──
A23: R&D Expense | B23: OpEx | C23: 1673 | D23: 1682 | E23: 1700 | F23: 1752 | G23: 6807 | H23: 6639 | I23: =G23-H23 -> 168 | J23: =IF(H23<>0,(G23-H23)/ABS(H23),"NM") -> 0.025305016 | K23: AI & hybrid cloud investment continuing
A24: SG&A Expense | B24: OpEx | C24: 4098 | D24: 3979 | E24: 3830 | F24: 4261 | G24: 16168 | H24: 15603 | I24: =G24-H24 -> 565 | J24: =IF(H24<>0,(G24-H24)/ABS(H24),"NM") -> 0.036210985 | K24: Includes restructuring & HashiCorp integration
A25: Pension Settlement Charge | B25: OpEx | C25: 0 | D25: 0 | E25: 3100 | F25: 0 | G25: 3100 | H25: 0 | I25: =G25-H25 -> 3100 | J25: =IF(H25<>0,(G25-H25)/ABS(H25),"NM") -> NM | K25: Non-cash; Q3 charge via Prudential annuity transfer
A26: Other (Income)/Expense | B26: OpEx | C26: 195 | D26: 183 | E26: 210 | G26: 2779 | H26: 3368 | I26: =G26-H26 -> -589 | J26: =IF(H26<>0,(G26-H26)/ABS(H26),"NM") -> -0.17488124 | K26: Net of interest income & other items
A27: TOTAL OPERATING EXPENSES | B27: OpEx | C27: 5966 | D27: 5844 | E27: 8840 | F27: 6004 | G27: 25854 | H27: 25610 | I27: =G27-H27 -> 244 | J27: =IF(H27<>0,(G27-H27)/ABS(H27),"NM") -> 0.0095275283 | K27: Elevated by non-cash $3.1B pension charge
A29: ── PROFIT METRICS ──
A30: EBIT (Operating Income) | B30: Profit | C30: 1904 | D30: 3339 | E30: -502 | F30: 4508 | G30: 10049 | H30: 8851 | I30: =G30-H30 -> 1198 | J30: =IF(H30<>0,(G30-H30)/ABS(H30),"NM") -> 0.13535194 | K30: Strong underlying ops; Q3 distorted by pension
A31: EBIT Margin % | B31: Profit | C31: 13.2% | D31: 21.1% | E31: -3.4% | F31: 25.7% | G31: 16.0% | H31: 14.3% | I31: Adjusted EBIT margin healthy at ~20%+ | K31: Adjusted EBIT margin healthy at ~20%+
A32: Income Before Tax | B32: Profit | C32: 1078 | D32: 2931 | E32: -908 | F32: 2696 | G32: 5797 | H32: 8690 | I32: =G32-H32 -> -2893 | J32: =IF(H32<>0,(G32-H32)/ABS(H32),"NM") -> -0.33291139 | K32: FY24 down 33% — pension charge impact
A33: Income Tax (Benefit)/Expense | B33: Profit | C33: 200 | D33: 340 | E33: -600 | F33: -158 | G33: -218 | H33: 1176 | I33: =G33-H33 -> -1394 | J33: =IF(H33<>0,(G33-H33)/ABS(H33),"NM") -> -1.1853741 | K33: Tax benefit in FY24 vs expense in FY23
A34: NET INCOME | B34: Profit | C34: 878 | D34: 2591 | E34: -308 | F34: 2862 | G34: 6023 | H34: 7502 | I34: =G34-H34 -> -1479 | J34: =IF(H34<>0,(G34-H34)/ABS(H34),"NM") -> -0.19714743 | K34: Down 19.7% YoY — all due to pension charge
A35: Net Income Margin % | B35: Profit | C35: 6.1% | D35: 16.4% | E35: -2.1% | F35: 16.3% | G35: 9.6% | H35: 12.1% | I35: Strip pension: operational margin much stronger | K35: Strip pension: operational margin much stronger
A36: Operating Non-GAAP EPS | B36: Profit | C36: $2.31 | D36: $2.43 | E36: $2.30 | F36: $3.29 | G36: $10.33 | H36: $9.62 | I36: Up 7.4% YoY — cleanest profit metric | K36: Up 7.4% YoY — cleanest profit metric
A37: Free Cash Flow | B37: Profit | C37: 1900 | D37: 2600 | E37: 2090 | F37: 5900 | G37: 12490 | H37: 11248 | I37: =G37-H37 -> 1242 | J37: =IF(H37<>0,(G37-H37)/ABS(H37),"NM") -> 0.11041963 | K37: Exceeded $12B FY guidance; strong cash gen

Sheet Segment_Revenue
A1: IBM — Segment Revenue Deep-Dive | FY 2024 (USD $M)
A2: Segment | B2: Sub-Segment | C2: Q1 2024 | D2: Q2 2024 | E2: Q3 2024 | F2: Q4 2024 | G2: FY 2024 | H2: FY 2023 | I2: YoY $M | J2: YoY %
A3: SOFTWARE | B3: Hybrid Platform & Solutions | C3: 3912 | D3: 4580 | E3: 4420 | F3: 4852 | G3: 17764 | H3: 16296 | I3: =G3-H3 -> 1468 | J3: =IF(H3<>0,(G3-H3)/ABS(H3),"NM") -> 0.090083456
A4: SOFTWARE | B4: Transaction Processing | C4: 1990 | D4: 2160 | E4: 2100 | F4: 2264 | G4: 8514 | H4: 8163 | I4: =G4-H4 -> 351 | J4: =IF(H4<>0,(G4-H4)/ABS(H4),"NM") -> 0.042998897
A5: SOFTWARE | B5: TOTAL SOFTWARE | C5: 5902 | D5: 6740 | E5: 6520 | F5: 7116 | G5: 26278 | H5: 24459 | I5: =G5-H5 -> 1819 | J5: =IF(H5<>0,(G5-H5)/ABS(H5),"NM") -> 0.074369353
A6: CONSULTING | B6: Business Transformation | C6: 2010 | D6: 2024 | E6: 1987 | F6: 2050 | G6: 8071 | H6: 8100 | I6: =G6-H6 -> -29 | J6: =IF(H6<>0,(G6-H6)/ABS(H6),"NM") -> -0.0035802469
A7: CONSULTING | B7: Technology Consulting | C7: 1700 | D7: 1716 | E7: 1683 | F7: 1754 | G7: 6853 | H7: 7025 | I7: =G7-H7 -> -172 | J7: =IF(H7<>0,(G7-H7)/ABS(H7),"NM") -> -0.024483986
A8: CONSULTING | B8: Application Operations | C8: 1504 | D8: 1460 | E8: 1480 | F8: 1532 | G8: 5976 | H8: 5947 | I8: =G8-H8 -> 29 | J8: =IF(H8<>0,(G8-H8)/ABS(H8),"NM") -> 0.0048764083
A9: CONSULTING | B9: TOTAL CONSULTING | C9: 5214 | D9: 5200 | E9: 5150 | F9: 5336 | G9: 20900 | H9: 21072 | I9: =G9-H9 -> -172 | J9: =IF(H9<>0,(G9-H9)/ABS(H9),"NM") -> -0.0081624905
A10: INFRASTRUCTURE | B10: Hybrid Infrastructure | C10: 1920 | D10: 2388 | E10: 1980 | F10: 2760 | G10: 9048 | H10: 9635 | I10: =G10-H10 -> -587 | J10: =IF(H10<>0,(G10-H10)/ABS(H10),"NM") -> -0.060923716
A11: INFRASTRUCTURE | B11: Infrastructure Support | C11: 1035 | D11: 1261 | E11: 1063 | F11: 1388 | G11: 4747 | H11: 4593 | I11: =G11-H11 -> 154 | J11: =IF(H11<>0,(G11-H11)/ABS(H11),"NM") -> 0.033529284
A12: INFRASTRUCTURE | B12: TOTAL INFRASTRUCTURE | C12: 2955 | D12: 3649 | E12: 3043 | F12: 4148 | G12: 13795 | H12: 14228 | I12: =G12-H12 -> -433 | J12: =IF(H12<>0,(G12-H12)/ABS(H12),"NM") -> -0.030432949
A13: FINANCING | B13: IBM Financing & Other | C13: 389 | D13: 211 | E13: 257 | F13: 923 | G13: 1780 | H13: 2101 | I13: =G13-H13 -> -321 | J13: =IF(H13<>0,(G13-H13)/ABS(H13),"NM") -> -0.15278439
A14: TOTAL IBM | B14: All Segments | C14: 14460 | D14: 15800 | E14: 14970 | F14: 17523 | G14: 62753 | H14: 61860 | I14: =G14-H14 -> 893 | J14: =IF(H14<>0,(G14-H14)/ABS(H14),"NM") -> 0.014435823

Sheet KPI_Summary
A1: IBM FY 2024 — Key Performance Indicators at a Glance
A2: KPI | B2: FY 2024 Value | C2: vs FY 2023 | D2: Signal | E2: Analyst Commentary
A3: Total Revenue | B3: $62,753M | C3: +1.4% YoY | D3: ▲ | E3: Revenue growth modest; +3% at constant currency — in line with IBM mid-single-digit model
A4: Gross Profit | B4: $35,903M | C4: +4.2% YoY | D4: ▲ | E4: Gross profit growing faster than revenue — margin expansion story
A5: Gross Profit Margin | B5: 57.2% | C5: +1.5 pts YoY | D5: ▲ | E5: Favorable mix shift: high-margin Software now biggest segment
A6: Software Revenue | B6: $26,278M | C6: +7.5% YoY | D6: ▲ | E6: IBM's star segment — Red Hat up 14% in Q3; AI/hybrid cloud driving growth
A7: Consulting Revenue | B7: $20,900M | C7: -0.8% YoY | D7: ▼ | E7: Macro headwinds; client discretionary spending cautious in 2024
A8: Infrastructure Revenue | B8: $13,795M | C8: -3.0% YoY | D8: ▼ | E8: z16 mainframe late in product cycle — z17 refresh expected 2025
A9: Software Gross Margin | B9: ~83% | C9: Highest segment | D9: ▲ | E9: Best-in-class margin; Red Hat and transaction processing highly profitable
A10: Consulting Gross Margin | B10: ~27% | C10: Competitive pressure | D10: ◆ | E10: Labor-intensive; improvement needed to drive overall margin expansion
A11: Infrastructure Gross Margin | B11: ~51% | C11: Stable | D11: ◆ | E11: Hardware/software mix drives margin; stable despite revenue decline
A12: Total COGS | B12: $26,850M | C12: -2.0% YoY | D12: ▲ | E12: Cost discipline improving — COGS falling while revenue rises
A13: R&D Expense | B13: $6,807M | C13: +2.5% YoY | D13: ◆ | E13: Investment in watsonx AI and hybrid cloud platform continuing
... A26: HashiCorp Acquisition | B26: $6,400M enterprise value | C26: Closed 2024 | D26: ◆ | E26: Strengthens hybrid cloud platform; accretive to EBITDA within year 1

Sheet README
A1: IBM Corporation — FY 2024 Financial Dataset
A2: Portfolio Project | Jane Chisom Raymond | Financial BI Analytics & Accounting
A4: PRIMARY SOURCE: | B4: IBM 2024 Annual Report — SEC 10-K Exhibit 13, filed February 25, 2025
A5: URL: | B5: sec.gov/Archives/edgar/data/51143/000005114325000015/ibm-20241231_d2.htm
A6: QUARTERLY DATA: | B6: IBM Q1-Q4 2024 Earnings Press Releases (newsroom.ibm.com)
A8: SHEETS:
A9: Quarterly_PL | B9: Full P&L: Revenue, COGS, Gross Profit, OpEx, EBIT, Net Income — quarterly + full year
A10: Segment_Revenue | B10: Software / Consulting / Infrastructure / Financing — quarterly breakdown
A11: KPI_Summary | B11: 24 KPIs with analyst signals and commentary
A13: CURRENCY: | B13: All figures USD Millions ($M) unless stated
A14: FISCAL YEAR: | B14: January 1 — December 31, 2024
A15: KEY STORY: | B15: Software growing fast (83% margin). Consulting flat. Net income down only due to $3.1B non-cash pension charge.
A16: BEST METRIC: | B16: Use Operating Non-GAAP EPS ($10.33, +7.4%) for true operational performance view.
